[2023-09-20 16:51:56,868][ignite.engine.engine.Engine][INFO] - Engine run starting with max_epochs=1.
[2023-09-20 16:51:57,011][ignite.engine.engine.Engine][ERROR] - Current run is terminating due to exception: Caught IndexError in DataLoader worker process 0.
Original Traceback (most recent call last):
  File "/home/seppanen/miniconda3/envs/bts/lib/python3.10/site-packages/torch/utils/data/_utils/worker.py", line 302, in _worker_loop
    data = fetcher.fetch(index)
  File "/home/seppanen/miniconda3/envs/bts/lib/python3.10/site-packages/torch/utils/data/_utils/fetch.py", line 58, in fetch
    data = [self.dataset[idx] for idx in possibly_batched_index]
  File "/home/seppanen/miniconda3/envs/bts/lib/python3.10/site-packages/torch/utils/data/_utils/fetch.py", line 58, in <listcomp>
    data = [self.dataset[idx] for idx in possibly_batched_index]
  File "/home/seppanen/mbts/datasets/kitti_360/kitti_360_dataset.py", line 779, in __getitem__
    if self.return_vox_sem:
  File "/home/seppanen/mbts/datasets/kitti_360/kitti_360_dataset.py", line 669, in load_vox_segmentations
    voxel[voxel == 255] = 0
IndexError: index 255 is out of bounds for axis 0 with size 46

[2023-09-20 16:51:57,012][ignite.engine.engine.Engine][ERROR] - Engine run is terminating due to exception: Caught IndexError in DataLoader worker process 0.
Original Traceback (most recent call last):
  File "/home/seppanen/miniconda3/envs/bts/lib/python3.10/site-packages/torch/utils/data/_utils/worker.py", line 302, in _worker_loop
    data = fetcher.fetch(index)
  File "/home/seppanen/miniconda3/envs/bts/lib/python3.10/site-packages/torch/utils/data/_utils/fetch.py", line 58, in fetch
    data = [self.dataset[idx] for idx in possibly_batched_index]
  File "/home/seppanen/miniconda3/envs/bts/lib/python3.10/site-packages/torch/utils/data/_utils/fetch.py", line 58, in <listcomp>
    data = [self.dataset[idx] for idx in possibly_batched_index]
  File "/home/seppanen/mbts/datasets/kitti_360/kitti_360_dataset.py", line 779, in __getitem__
    if self.return_vox_sem:
  File "/home/seppanen/mbts/datasets/kitti_360/kitti_360_dataset.py", line 669, in load_vox_segmentations
    voxel[voxel == 255] = 0
IndexError: index 255 is out of bounds for axis 0 with size 46

