[2023-09-14 13:32:40,189][ignite.engine.engine.Engine][INFO] - Engine run starting with max_epochs=1.
[2023-09-14 13:32:40,367][ignite.engine.engine.Engine][ERROR] - Current run is terminating due to exception: Caught IndexError in DataLoader worker process 0.
Original Traceback (most recent call last):
  File "/home/seppanen/miniconda3/envs/bts/lib/python3.10/site-packages/torch/utils/data/_utils/worker.py", line 302, in _worker_loop
    data = fetcher.fetch(index)
  File "/home/seppanen/miniconda3/envs/bts/lib/python3.10/site-packages/torch/utils/data/_utils/fetch.py", line 58, in fetch
    data = [self.dataset[idx] for idx in possibly_batched_index]
  File "/home/seppanen/miniconda3/envs/bts/lib/python3.10/site-packages/torch/utils/data/_utils/fetch.py", line 58, in <listcomp>
    data = [self.dataset[idx] for idx in possibly_batched_index]
  File "/home/seppanen/mbts/datasets/kitti_360/kitti_360_dataset.py", line 800, in __getitem__
    if self.return_bev_sem:
  File "/home/seppanen/mbts/datasets/kitti_360/kitti_360_dataset.py", line 695, in load_bev_segmentations
  File "/home/seppanen/mbts/datasets/kitti_360/kitti_360_dataset.py", line 539, in _prepare_inputs
IndexError: too many indices for tensor of dimension 1

[2023-09-14 13:32:40,367][ignite.engine.engine.Engine][ERROR] - Engine run is terminating due to exception: Caught IndexError in DataLoader worker process 0.
Original Traceback (most recent call last):
  File "/home/seppanen/miniconda3/envs/bts/lib/python3.10/site-packages/torch/utils/data/_utils/worker.py", line 302, in _worker_loop
    data = fetcher.fetch(index)
  File "/home/seppanen/miniconda3/envs/bts/lib/python3.10/site-packages/torch/utils/data/_utils/fetch.py", line 58, in fetch
    data = [self.dataset[idx] for idx in possibly_batched_index]
  File "/home/seppanen/miniconda3/envs/bts/lib/python3.10/site-packages/torch/utils/data/_utils/fetch.py", line 58, in <listcomp>
    data = [self.dataset[idx] for idx in possibly_batched_index]
  File "/home/seppanen/mbts/datasets/kitti_360/kitti_360_dataset.py", line 800, in __getitem__
    if self.return_bev_sem:
  File "/home/seppanen/mbts/datasets/kitti_360/kitti_360_dataset.py", line 695, in load_bev_segmentations
  File "/home/seppanen/mbts/datasets/kitti_360/kitti_360_dataset.py", line 539, in _prepare_inputs
IndexError: too many indices for tensor of dimension 1

